Workbook

Sheet DEBUT
A1: Désignation produit en anglais | B1: Désignation produit en francais | C1: remarques | D1: Prix d'achat unitaire HT
O2: TOTAL COMMANDE
O3: GREY RAL 7021 | P3: WHITE RAL 9003
A4: BACK PANEL 400X500 | B4: Fond 400 x 500 | D4: 3.20712
A5: BACK PANEL 500X500 | B5: fond 500 x 500 | D5: 4.10872
A6: BACK PANEL 400X700 | B6: Fond 400 x 700 | D6: 3.47
A7: BACK PANEL 500X700 | B7: fond 500 x 700 | D7: 4.27
A8: SLIDING BACK PANEL 400X700 | B8: fond extensible 400 | D8: 6.23
A9: SLIDING BACK PANEL 500X700 | B9: Fond extensible 500 | D9: 7.658
A10: SHELF MONOBLOCK (WITHOUT C LABELS) 200X500 | B10: Tablette 200 x 500 | C10: SEPERATOR WITHOUT HOLES - FLAT separateur sans trou | D10: 2.4472
A11: SHELF MONOBLOCK (WITHOUT C LABELS) 200X700 | B11: Tablette 200 x 700 | C11: SEPERATOR WITHOUT HOLES - FLAT separateur sans trou | D11: 3.38744
A12: SHELF MONOBLOCK (WITHOUT C LABELS) 200X700 | B12: Tablette 200 x 700 pour bacs soldeurs | C12: GLASS SEPERATOR PERFORATED perforation pour separateur verre | D12: 3.38744
A13: SHELF MONOBLOCK (WITHOUT C LABELS) 300X700 | B13: Tabette 300 x 700 pour bacs soldeurs | C13: GLASS SEPERATOR PERFORATED perforation pour separateur verre | D13: 4.0572
A14: SHELF MONOBLOCK (WITHOUT C LABELS) 400 X 700 | B14: Tabette 400 x 700 pour bacs soldeurs | C14: GLASS SEPERATOR PERFORATED perforation pour separateur verre | D14: 4.0572
A15: SHELF MONOBLOCK (WITHOUT C LABELS) 200 X 500 | B15: Tabette 200 x 500 pour bacs soldeurs | C15: GLASS SEPERATOR PERFORATED perforation pour separateur verre | D15: 4.0572
A16: SHELF MONOBLOCK (WITHOUT C LABELS) 300 X 500 | B16: Tabette 300 x 500 pour bacs soldeurs | C16: GLASS SEPERATOR PERFORATED perforation pour separateur verre | D16: 4.0572
A17: SHELF MONOBLOCK (WITHOUT C LABELS) 400 X 500 | B17: Tabette 400 x 500 pour bacs soldeurs | C17: GLASS SEPERATOR PERFORATED perforation pour separateur verre | D17: 4.0572
A18: SHELF MONOBLOCK (WITHOUT C LABELS) 300X500 | B18: Tabette 300 x 500 sans trou | C18: SEPERATOR WITHOUT HOLES - FLAT separateur sans trou | D18: 4.0572
A19: SHELF MONOBLOCK (WITHOUT C LABELS) 400X500 | B19: Tabette 400 x 500 sans trou | C19: SEPERATOR WITHOUT HOLES - FLAT separateur sans trou | D19: 4.0572
A20: SHELF MONOBLOCK (WITHOUT C LABELS) 300X700 | B20: Tabette 300 x 700 sans trou | C20: SEPERATOR WITHOUT HOLES - FLAT separateur sans trou | D20: 4.0572
A21: SHELF MONOBLOCK (WITHOUT C LABELS) 400X700 | B21: Tablette 400 x 700 sans trou | C21: SEPERATOR WITHOUT HOLES - FLAT separateur sans trou | D21: 5.3
... A23: PERFORATED SHELF MONOBLOCK (WITHOUT C LABELS) 400X700 | B23: TABLETTE PERFORÉE (SANS PORTE ETIQUETTE) 400 X 700 | C23: STANDART PERFORATED SHELF Tablette standard perforée | D23: 5.30656
A24: GLASS SEPERATOR APPARATUS-CORNER | B24: SEPARATEUR VERRE D'ANGLE | D24: 0.24
A25: GLASS SEPERATOR APPARATUS-FLAT | B25: SEPARATEUR VERRE PLAT | D25: 0.17
A26: SIDE GLASS SEPERATOR 200X180 , 6MM TEMPERED GLASS | B26: VERRE LATÉRAL VERRE TREMPÉ 6MM 200 X 180 | D26: 7.2
A27: SIDE GLASS SEPERATOR 300X180 , 6MM TEMPERED GLASS | B27: VERRE LATÉRAL VERRE TREMPÉ 6MM 300 X 180 | D27: 7.2
A28: SIDE GLASS SEPERATOR 400X180 , 6MM TEMPERED GLASS | B28: VERRE LATÉRAL VERRE TREMPÉ 6MM 400 X 180 | D28: 7.2
A29: FRONT WINDOW SEPERATOR L:700 H:100, 6MM TEMPERED GLASS | B29: VERRE FRONTAL VERRE TREMPÉ 6 MM 700 X 100 | D29: 7.2
A30: FRONT WINDOW SEPERATOR L:500 H:100, 6MM TEMPERED GLASS | B30: VERRE FRONTAL VERRE TREMPÉ 6 MM 500 X 100 | D30: 7.2
A31: FRONT WINDOW SEPERATOR L:500 H:100, 6MM TEMPERED GLASS | B31: VERRE FRONTAL VERRE TREMPÉ 6 MM 500 X 100 | D31: 7.2
A32: GLASS SHELF (6mm TEMPERED) 200X500 | B32: Tablette verre 200 x 500 | C32: FOR THE MIDDLE COUNTER DESK pour inter comptoir | D32: 8.792
A33: GLASS SHELF (6mm TEMPERED) 200X500 | B33: Tablettes verres 200 X 500 | C33: FOR THE WALL UNIT Pour les linéaires muraux | D33: 8.792
A34: GLASS SHELF (6mm TEMPERED) 200X700 | B34: Tablettes verres 200 X 700 | C34: FOR THE WALL UNIT Pour les linéaires muraux | D34: 9.618
A35: GLASS SHELF (6mm TEMPERED) 300X500 | B35: Tablettes verres 300 X 500 | C35: FOR THE WALL UNIT Pour les linéaires muraux | D35: 9.618
A36: GLASS SHELF (6mm TEMPERED) 300X700 | B36: Tablettes verres 300 X 700 | C36: FOR THE WALL UNIT Pour les linéaires muraux | D36: 9.618
A37: SLIDING SHELF (WITHOUT HOLES) 200X700 | B37: Tablettes extensibles sans trou 200 X 700 | C37: RAL 7201 | D37: 6.622
A38: SLIDING SHELF (WITHOUT HOLES) 300X700 | B38: Tablettes extensibles sans trou 300 X 700 | C38: RAL 7201 | D38: 6.622
A39: SLIDING SHELF (WITHOUT HOLES) 400X700 | B39: Tablettes extensibles sans trou 400 X 700 | C39: RAL 9003 | D39: 8.652
A40: GLASS SHELF CONSOLE 200X700 | B40: Console tablettes verre 200 X 700 | C40: RAL 7201 | D40: 7.22
A41: GLASS SHELF CONSOLE (ONE PIECE) 200X500 | B41: Console tablettes verre 200 X 500 | C41: RAL 7201 | D41: 5.16
...

Sheet LINÉAIRE  VERRE Base + 8
A1: Désignation produit en anglais | B1: Désignation produit en francais | C1: remarques | D1: Prix d'achat unitaire HT | E1: LINEAIRE 2200 x 700 x 300 verre base +8 | F1: SUITE LINEAIRE 2200 x 700 x 300 verre base +8 | G1: LINEAIRE 2200 x 700 x 200 verre base +8 | H1: SUITE LINEAIRE 2200 x 700 x 200 verre base +8 | I1: LINEAIRE 2200 x 500 x 200 verre base +8 | J1: LINEAIRE 2200 x 500 x 300 verre base +8
D3: Quantité | E3: 0 | F3: 0 | G3: 0 | H3: 0 | I3: 0 | J3: 0 | O3: TOTAL | P3: prix
A4: BACK PANEL 400X500 | B4: Fond 400 x 500 | D4: 3.20712 | I4: =4*I3 -> 0 | J4: =4*J3 -> 0 | O4: =SUM(E4:J4) -> 0 | P4: =D4*O4 -> 0
A5: BACK PANEL 500X500 | B5: fond 500 x 500 | D5: 4.10872 | I5: =1*I3 -> 0 | J5: =1*J3 -> 0 | O5: =SUM(E5:J5) -> 0 | P5: =D5*O5 -> 0
A6: BACK PANEL 400X700 | B6: Fond 400 x 700 | D6: 3.47 | E6: =4*E3 -> 0 | F6: =4*F3 -> 0 | G6: =4*G3 -> 0 | H6: =4*H3 -> 0 | O6: =SUM(E6:J6) -> 0 | P6: =D6*O6 -> 0
A7: BACK PANEL 500X700 | B7: fond 500 x 700 | D7: 4.27 | E7: =1*E3 -> 0 | F7: =1*F3 -> 0 | G7: =1*G3 -> 0 | H7: =1*H3 -> 0 | O7: =SUM(E7:J7) -> 0 | P7: =D7*O7 -> 0
A8: SLIDING BACK PANEL 400X700 | B8: fond extensible 400 | D8: 6.23 | O8: =SUM(E8:J8) -> 0 | P8: =D8*O8 -> 0
A9: SLIDING BACK PANEL 500X700 | B9: Fond extensible 500 | D9: 7.658 | O9: =SUM(E9:J9) -> 0 | P9: =D9*O9 -> 0
A10: SHELF MONOBLOCK (WIthout c labels) 200X500 | B10: Tablette 200 x 500 | C10: SEPERATOR WITHOUT HOLES - FLAT separateur sans trou | D10: 2.4472 | I10: =1*I3 -> 0 | O10: =SUM(E10:J10) -> 0 | P10: =D10*O10 -> 0
A11: SHELF MONOBLOCK (WITHOUT C LABELS) 200X700 | B11: Tablette 200 x 700 | C11: SEPERATOR WITHOUT HOLES - FLAT separateur sans trou | D11: 3.38744 | G11: =1*G3 -> 0 | H11: =1*H3 -> 0 | O11: =SUM(E11:J11) -> 0 | P11: =D11*O11 -> 0
A12: SHELF MONOBLOCK (WITHOUT C LABELS) 200X700 | B12: Tablette 200 x 700 pour bacs soldeurs | C12: GLASS SEPERATOR PERFORATED perforation pour separateur verre | D12: 3.38744 | O12: =SUM(E12:J12) -> 0 | P12: =D12*O12 -> 0
A13: SHELF MONOBLOCK (WITHOUT C LABELS) 300X700 | B13: Tabette 300 x 700 pour bacs soldeurs | C13: GLASS SEPERATOR PERFORATED perforation pour separateur verre | D13: 4.0572 | O13: =SUM(E13:J13) -> 0 | P13: =D13*O13 -> 0
A14: SHELF MONOBLOCK (WITHOUT C LABELS) 400 X 700 | B14: Tabette 400 x 700 pour bacs soldeurs | C14: GLASS SEPERATOR PERFORATED perforation pour separateur verre | D14: 4.0572 | O14: =SUM(E14:J14) -> 0 | P14: =D14*O14 -> 0
A15: SHELF MONOBLOCK (WITHOUT C LABELS) 200 X 500 | B15: Tabette 200 x 500 pour bacs soldeurs | C15: GLASS SEPERATOR PERFORATED perforation pour separateur verre | D15: 4.0572 | O15: =SUM(E15:J15) -> 0 | P15: =D15*O15 -> 0
A16: SHELF MONOBLOCK (WITHOUT C LABELS) 300 X 500 | B16: Tabette 300 x 500 pour bacs soldeurs | C16: GLASS SEPERATOR PERFORATED perforation pour separateur verre | D16: 4.0572 | O16: =SUM(E16:J16) -> 0 | P16: =D16*O16 -> 0
A17: SHELF MONOBLOCK (WITHOUT C LABELS) 400 X 500 | B17: Tabette 400 x 500 pour bacs soldeurs | C17: GLASS SEPERATOR PERFORATED perforation pour separateur verre | D17: 4.0572 | O17: =SUM(E17:J17) -> 0 | P17: =D17*O17 -> 0
A18: SHELF MONOBLOCK (WITHOUT C LABELS) 300X500 | B18: Tabette 300 x 500 sans trou | C18: SEPERATOR WITHOUT HOLES - FLAT separateur sans trou | D18: 4.0572 | J18: =1*J3 -> 0 | O18: =SUM(E18:J18) -> 0 | P18: =D18*O18 -> 0
A19: SHELF MONOBLOCK (WITHOUT C LABELS) 300X700 | B19: Tabette 300 x 700 sans trou | C19: SEPERATOR WITHOUT HOLES - FLAT separateur sans trou | D19: 4.0572 | E19: =1*E3 -> 0 | F19: =1*F3 -> 0 | O19: =SUM(E19:J19) -> 0 | P19: =D19*O19 -> 0
A20: SHELF MONOBLOCK (WITHOUT C LABELS) 400X700 | B20: Tablette 400 x 700 sans trou | C20: SEPERATOR WITHOUT HOLES - FLAT separateur sans trou | D20: 5.3 | O20: =SUM(E20:J20) -> 0 | P20: =D20*O20 -> 0
A21: SHELF MONOBLOCK (WITHOUT C LABELS) 400X500 | B21: Tabette 400 x 500 sans trou | C21: SEPERATOR WITHOUT HOLES - FLAT separateur sans trou | D21: 4.0572 | O21: =SUM(E21:J21) -> 0
A22: PERFORATED SHELF MONOBLOCK (WITHOUT C LABELS) 300X700 | B22: Tablette 300 x 700 perforée | C22: STANDART PERFORATED SHELF Tablette standard perforée | D22: 5.30656 | O22: =SUM(E22:J22) -> 0 | P22: =D22*O22 -> 0
A23: PERFORATED SHELF MONOBLOCK (WITHOUT C LABELS) 400X700 | B23: TABLETTE PERFORÉE (SANS PORTE ETIQUETTE) 400 X 700 | C23: STANDART PERFORATED SHELF Tablette standard perforée | D23: 5.30656 | O23: =SUM(E23:J23) -> 0 | P23: =D23*O23 -> 0
A24: GLASS SEPERATOR APPARATUS-CORNER | B24: SEPARATEUR VERRE D'ANGLE | D24: 0.24 | O24: =SUM(E24:J24) -> 0 | P24: =D24*O24 -> 0
A25: GLASS SEPERATOR APPARATUS-FLAT | B25: SEPARATEUR VERRE PLAT | D25: 0.17 | O25: =SUM(E25:J25) -> 0 | P25: =D25*O25 -> 0
A26: SIDE GLASS SEPERATOR 200X180 , 6MM TEMPERED GLASS | B26: VERRE LATÉRAL VERRE TREMPÉ 6MM 200 X 180 | D26: 7.2 | O26: =SUM(E26:J26) -> 0 | P26: =D26*O26 -> 0
A27: SIDE GLASS SEPERATOR 300X180 , 6MM TEMPERED GLASS | B27: VERRE LATÉRAL VERRE TREMPÉ 6MM 300 X 180 | D27: 7.2 | O27: =SUM(E27:J27) -> 0 | P27: =D27*O27 -> 0
A28: SIDE GLASS SEPERATOR 400X180 , 6MM TEMPERED GLASS | B28: VERRE LATÉRAL VERRE TREMPÉ 6MM 400 X 180 | D28: 7.2 | O28: =SUM(E28:J28) -> 0 | P28: =D28*O28 -> 0
A29: FRONT WINDOW SEPERATOR L:700 H:100, 6MM TEMPERED GLASS | B29: VERRE FRONTAL VERRE TREMPÉ 6 MM 700 X 100 | D29: 7.2 | O29: =SUM(E29:J29) -> 0 | P29: =D29*O29 -> 0
A30: FRONT WINDOW SEPERATOR L:500 H:100, 6MM TEMPERED GLASS | B30: VERRE FRONTAL VERRE TREMPÉ 6 MM 500 X 100 | D30: 7.2 | O30: =SUM(E30:J30) -> 0 | P30: =D30*O30 -> 0
A31: FRONT WINDOW SEPERATOR L:500 H:100, 6MM TEMPERED GLASS | B31: VERRE FRONTAL VERRE TREMPÉ 6 MM 500 X 100 | D31: 7.2 | O31: =SUM(E31:J31) -> 0 | P31: =D31*O31 -> 0
A32: GLASS SHELF (6mm TEMPERED) 200X500 | B32: Tablette verre 200 x 500 | C32: FOR THE MIDDLE COUNTER DESK pour inter comptoir | D32: 8.792 | O32: =SUM(E32:J32) -> 0 | P32: =D32*O32 -> 0
A33: GLASS SHELF (6mm TEMPERED) 200X500 | B33: Tablettes verres 200 X 500 | C33: FOR THE WALL UNIT Pour les linéaires muraux | D33: 8.792 | I33: =8*I3 -> 0 | O33: =SUM(E33:J33) -> 0 | P33: =D33*O33 -> 0
A34: GLASS SHELF (6mm TEMPERED) 200X700 | B34: Tablettes verres 200 X 700 | C34: FOR THE WALL UNIT Pour les linéaires muraux | D34: 9.618 | G34: =8*G3 -> 0 | H34: =8*H3 -> 0 | O34: =SUM(E34:J34) -> 0 | P34: =D34*O34 -> 0
A35: GLASS SHELF (6mm TEMPERED) 300X500 | B35: Tablettes verres 300 X 500 | C35: FOR THE WALL UNIT Pour les linéaires muraux | D35: 9.618 | J35: =8*J3 -> 0 | O35: =SUM(E35:J35) -> 0 | P35: =D35*O35 -> 0
A36: GLASS SHELF (6mm TEMPERED) 300X700 | B36: Tablettes verres 300 X 700 | C36: FOR THE WALL UNIT Pour les linéaires muraux | D36: 9.618 | E36: =8*E3 -> 0 | F36: =8*F3 -> 0 | O36: =SUM(E36:J36) -> 0 | P36: =D36*O36 -> 0
A37: SLIDING SHELF (WITHOUT HOLES) 200X700 | B37: Tablettes extensibles sans trou 200 | C37: RAL 7021 | D37: 6.622 | O37: =SUM(E37:J37) -> 0 | P37: =D37*O37 -> 0
A38: SLIDING SHELF (WITHOUT HOLES) 300X700 | B38: Tablettes extensibles sans trou 300 X 700 | C38: RAL 7201 | D38: 6.622 | O38: =SUM(E38:J38) -> 0 | P38: =D38*O38 -> 0
A39: SLIDING SHELF (WITHOUT HOLES) 400X700 | B39: Tablettes extensibles sans trou 400 X 700 | C39: RAL 9003 | D39: 8.652 | O39: =SUM(E39:J39) -> 0 | P39: =D39*O39 -> 0
A40: GLASS SHELF CONSOLE 200X700 | B40: Console tablettes verre 200 X 700 | C40: RAL 7201 | D40: 7.22 | G40: =8*G3 -> 0 | H40: =8*H3 -> 0 | O40: =SUM(E40:J40) -> 0 | P40: =D40*O40 -> 0
A41: GLASS SHELF CONSOLE 200X500 | B41: Console tablettes verre 200 X 500 | C41: RAL 7201 | D41: 5.16 | I41: =8*I3 -> 0 | O41: =SUM(E41:J41) -> 0 | P41: =D41*O41 -> 0
...

Sheet LINÉAIREVERRE BASE + 9
A1: Désignation produit en anglais | B1: Désignation produit en francais | C1: remarques | D1: Prix d'achat unitaire HT | E1: LINEAIRE 2200 x 700 x 300 verre base +9 | F1: SUITE LINEAIRE 2200 x 700 x 300 verre base +9 | G1: LINEAIRE 2200 x 700 x 200 verre base +9 | H1: SUITE LINEAIRE 2200 x 700 x 200 verre base +9 | I1: LINEAIRE 2200 x 500 x 200 verre base +9 | J1: LINEAIRE 2200 x 500 x 300 verre base + 9
D3: Quantité | E3: 0 | F3: 0 | G3: 0 | H3: 0 | I3: 0 | J3: 0 | O3: TOTAL | P3: prix
A4: BACK PANEL 400X500 | B4: Fond 400 x 500 | D4: 3.20712 | I4: =4*I3 -> 0 | J4: =4*J3 -> 0 | O4: =SUM(E4:J4) -> 0 | P4: =D4*O4 -> 0
A5: BACK PANEL 500X500 | B5: fond 500 x 500 | D5: 4.10872 | I5: =1*I3 -> 0 | J5: =1*J3 -> 0 | O5: =SUM(E5:J5) -> 0 | P5: =D5*O5 -> 0
A6: BACK PANEL 400X700 | B6: Fond 400 x 700 | D6: 3.47 | E6: =4*E3 -> 0 | F6: =4*F3 -> 0 | G6: =4*G3 -> 0 | H6: =4*H3 -> 0 | O6: =SUM(E6:J6) -> 0 | P6: =D6*O6 -> 0
A7: BACK PANEL 500X700 | B7: fond 500 x 700 | D7: 4.27 | E7: =1*E3 -> 0 | F7: =1*F3 -> 0 | G7: =1*G3 -> 0 | H7: =1*H3 -> 0 | O7: =SUM(E7:J7) -> 0 | P7: =D7*O7 -> 0
A8: SLIDING BACK PANEL 400X700 | B8: fond extensible 400 | D8: 6.23 | O8: =SUM(E8:J8) -> 0 | P8: =D8*O8 -> 0
A9: SLIDING BACK PANEL 500X700 | B9: Fond extensible 500 | D9: 7.658 | O9: =SUM(E9:J9) -> 0 | P9: =D9*O9 -> 0
A10: SHELF MONOBLOCK (WIthout c labels) 200X500 | B10: Tablette 200 x 500 | C10: SEPERATOR WITHOUT HOLES - FLAT separateur sans trou | D10: 2.4472 | I10: =1*I3 -> 0 | O10: =SUM(E10:J10) -> 0 | P10: =D10*O10 -> 0
A11: SHELF MONOBLOCK (WITHOUT C LABELS) 200X700 | B11: Tablette 200 x 700 | C11: SEPERATOR WITHOUT HOLES - FLAT separateur sans trou | D11: 3.38744 | G11: =1*G3 -> 0 | H11: =1*H3 -> 0 | O11: =SUM(E11:J11) -> 0 | P11: =D11*O11 -> 0
A12: SHELF MONOBLOCK (WITHOUT C LABELS) 200X700 | B12: Tablette 200 x 700 pour bacs soldeurs | C12: GLASS SEPERATOR PERFORATED perforation pour separateur verre | D12: 3.38744 | O12: =SUM(E12:J12) -> 0 | P12: =D12*O12 -> 0
A13: SHELF MONOBLOCK (WITHOUT C LABELS) 300X700 | B13: Tabette 300 x 700 pour bacs soldeurs | C13: GLASS SEPERATOR PERFORATED perforation pour separateur verre | D13: 4.0572 | O13: =SUM(E13:J13) -> 0 | P13: =D13*O13 -> 0
A14: SHELF MONOBLOCK (WITHOUT C LABELS) 400 X 700 | B14: Tabette 400 x 700 pour bacs soldeurs | C14: GLASS SEPERATOR PERFORATED perforation pour separateur verre | D14: 4.0572 | O14: =SUM(E14:J14) -> 0 | P14: =D14*O14 -> 0
A15: SHELF MONOBLOCK (WITHOUT C LABELS) 200 X 500 | B15: Tabette 200 x 500 pour bacs soldeurs | C15: GLASS SEPERATOR PERFORATED perforation pour separateur verre | D15: 4.0572 | O15: =SUM(E15:J15) -> 0 | P15: =D15*O15 -> 0
A16: SHELF MONOBLOCK (WITHOUT C LABELS) 300 X 500 | B16: Tabette 300 x 500 pour bacs soldeurs | C16: GLASS SEPERATOR PERFORATED perforation pour separateur verre | D16: 4.0572 | O16: =SUM(E16:J16) -> 0 | P16: =D16*O16 -> 0
A17: SHELF MONOBLOCK (WITHOUT C LABELS) 400 X 500 | B17: Tabette 400 x 500 pour bacs soldeurs | C17: GLASS SEPERATOR PERFORATED perforation pour separateur verre | D17: 4.0572 | O17: =SUM(E17:J17) -> 0 | P17: =D17*O17 -> 0
A18: SHELF MONOBLOCK (WITHOUT C LABELS) 300X500 | B18: Tabette 300 x 500 sans trou | C18: SEPERATOR WITHOUT HOLES - FLAT separateur sans trou | D18: 4.0572 | J18: =1*J3 -> 0 | O18: =SUM(E18:J18) -> 0 | P18: =D18*O18 -> 0
A19: SHELF MONOBLOCK (WITHOUT C LABELS) 400X500 | B19: Tabette 400 x 500 sans trou | C19: SEPERATOR WITHOUT HOLES - FLAT separateur sans trou | D19: 4.0572
A20: SHELF MONOBLOCK (WITHOUT C LABELS) 300X700 | B20: Tabette 300 x 700 sans trou | C20: SEPERATOR WITHOUT HOLES - FLAT separateur sans trou | D20: 4.0572 | E20: =1*E3 -> 0 | F20: =1*F3 -> 0 | O20: =SUM(E20:J20) -> 0 | P20: =D20*O20 -> 0
A21: SHELF MONOBLOCK (WITHOUT C LABELS) 400X700 | B21: Tablette 400 x 700 sans trou | C21: SEPERATOR WITHOUT HOLES - FLAT separateur sans trou | D21: 5.3 | O21: =SUM(E21:J21) -> 0 | P21: =D21*O21 -> 0
A22: PERFORATED SHELF MONOBLOCK (WITHOUT C LABELS) 300X700 | B22: Tablette 300 x 700 perforée | C22: STANDART PERFORATED SHELF Tablette standard perforée | D22: 5.30656 | O22: =SUM(E22:J22) -> 0 | P22: =D22*O22 -> 0
A23: PERFORATED SHELF MONOBLOCK (WITHOUT C LABELS) 400X700 | B23: TABLETTE PERFORÉE (SANS PORTE ETIQUETTE) 400 X 700 | C23: STANDART PERFORATED SHELF Tablette standard perforée | D23: 5.30656 | O23: =SUM(E23:J23) -> 0 | P23: =D23*O23 -> 0
A24: GLASS SEPERATOR APPARATUS-CORNER | B24: SEPARATEUR VERRE D'ANGLE | D24: 0.24 | O24: =SUM(E24:J24) -> 0 | P24: =D24*O24 -> 0
A25: GLASS SEPERATOR APPARATUS-FLAT | B25: SEPARATEUR VERRE PLAT | D25: 0.17 | O25: =SUM(E25:J25) -> 0 | P25: =D25*O25 -> 0
A26: SIDE GLASS SEPERATOR 200X180 , 6MM TEMPERED GLASS | B26: VERRE LATÉRAL VERRE TREMPÉ 6MM 200 X 180 | D26: 7.2 | O26: =SUM(E26:J26) -> 0 | P26: =D26*O26 -> 0
A27: SIDE GLASS SEPERATOR 300X180 , 6MM TEMPERED GLASS | B27: VERRE LATÉRAL VERRE TREMPÉ 6MM 300 X 180 | D27: 7.2 | O27: =SUM(E27:J27) -> 0 | P27: =D27*O27 -> 0
A28: SIDE GLASS SEPERATOR 400X180 , 6MM TEMPERED GLASS | B28: VERRE LATÉRAL VERRE TREMPÉ 6MM 400 X 180 | D28: 7.2 | O28: =SUM(E28:J28) -> 0 | P28: =D28*O28 -> 0
A29: FRONT WINDOW SEPERATOR L:700 H:100, 6MM TEMPERED GLASS | B29: VERRE FRONTAL VERRE TREMPÉ 6 MM 700 X 100 | D29: 7.2 | O29: =SUM(E29:J29) -> 0 | P29: =D29*O29 -> 0
A30: FRONT WINDOW SEPERATOR L:500 H:100, 6MM TEMPERED GLASS | B30: VERRE FRONTAL VERRE TREMPÉ 6 MM 500 X 100 | D30: 7.2 | O30: =SUM(E30:J30) -> 0 | P30: =D30*O30 -> 0
A31: FRONT WINDOW SEPERATOR L:500 H:100, 6MM TEMPERED GLASS | B31: VERRE FRONTAL VERRE TREMPÉ 6 MM 500 X 100 | D31: 7.2 | O31: =SUM(E31:J31) -> 0 | P31: =D31*O31 -> 0
A32: GLASS SHELF (6mm TEMPERED) 200X500 | B32: Tablette verre 200 x 500 | C32: FOR THE MIDDLE COUNTER DESK pour inter comptoir | D32: 8.792 | O32: =SUM(E32:J32) -> 0 | P32: =D32*O32 -> 0
A33: GLASS SHELF (6mm TEMPERED) 200X500 | B33: Tablettes verres 200 X 500 | C33: FOR THE WALL UNIT Pour les linéaires muraux | D33: 8.792 | I33: =9*I3 -> 0 | O33: =SUM(E33:J33) -> 0 | P33: =D33*O33 -> 0
A34: GLASS SHELF (6mm TEMPERED) 200X700 | B34: Tablettes verres 200 X 700 | C34: FOR THE WALL UNIT Pour les linéaires muraux | D34: 9.618 | G34: =9*G3 -> 0 | H34: =9*H3 -> 0 | O34: =SUM(E34:J34) -> 0 | P34: =D34*O34 -> 0
A35: GLASS SHELF (6mm TEMPERED) 300X500 | B35: Tablettes verres 300 X 500 | C35: FOR THE WALL UNIT Pour les linéaires muraux | D35: 9.618 | J35: =9*J3 -> 0 | O35: =SUM(E35:J35) -> 0 | P35: =D35*O35 -> 0
A36: GLASS SHELF (6mm TEMPERED) 300X700 | B36: Tablettes verres 300 X 700 | C36: FOR THE WALL UNIT Pour les linéaires muraux | D36: 9.618 | E36: =9*E3 -> 0 | F36: =9*F3 -> 0 | O36: =SUM(E36:J36) -> 0 | P36: =D36*O36 -> 0
A37: SLIDING SHELF (WITHOUT HOLES) 200X700 | B37: Tablettes extensibles sans trou 200 | C37: RAL 7021 | D37: 6.622 | O37: =SUM(E37:J37) -> 0 | P37: =D37*O37 -> 0
A38: SLIDING SHELF (WITHOUT HOLES) 300X700 | B38: Tablettes extensibles sans trou 300 X 700 | C38: RAL 7201 | D38: 6.622 | O38: =SUM(E38:J38) -> 0 | P38: =D38*O38 -> 0
A39: SLIDING SHELF (WITHOUT HOLES) 400X700 | B39: Tablettes extensibles sans trou 400 X 700 | C39: RAL 9003 | D39: 8.652 | O39: =SUM(E39:J39) -> 0 | P39: =D39*O39 -> 0
A40: GLASS SHELF CONSOLE 200X700 | B40: Console tablettes verre 200 X 700 | C40: RAL 7201 | D40: 7.22 | G40: =9*G3 -> 0 | H40: =9*H3 -> 0 | O40: =SUM(E40:J40) -> 0 | P40: =D40*O40 -> 0
A41: GLASS SHELF CONSOLE 200X500 | B41: Console tablettes verre 200 X 500 | C41: RAL 7201 | D41: 5.16 | I41: =9*I3 -> 0 | O41: =SUM(E41:J41) -> 0 | P41: =D41*O41 -> 0
...

Sheet LINÉAIRE Métal base + 7
A1: Désignation produit en anglais | B1: Désignation produit en francais | C1: remarques | D1: Prix d'achat unitaire HT | E1: LINEAIRE 2200 x 700 x 300 Métal base +7 | F1: SUITE LINEAIRE 2200 x 700 x 300 Métal base +7 | G1: LINEAIRE 2200 x 700 x 200 métal base +7 | H1: SUITE LINEAIRE 2200 x 700 x 200 métal base +7 | I1: LINEAIRE 2200 x 500 x 200 métal base +7 | J1: LINEAIRE 2200 x 500 x 300 métal base +7
D3: QUANTITÉ | E3: 0 | F3: 0 | G3: 0 | H3: 0 | I3: 0 | J3: 0 | O3: TOTAL | P3: PRIX
A4: BACK PANEL 400X500 | B4: Fond 400 x 500 | D4: 3.20712 | I4: =4*I3 -> 0 | J4: =4*J3 -> 0 | O4: =SUM(E4:J4) -> 0 | P4: =D4*O4 -> 0
A5: BACK PANEL 500X500 | B5: fond 500 x 500 | D5: 4.10872 | I5: =1*I3 -> 0 | J5: =1*J3 -> 0 | O5: =SUM(E5:J5) -> 0 | P5: =D5*O5 -> 0
A6: BACK PANEL 400X700 | B6: Fond 400 x 700 | D6: 3.47 | E6: =4*E3 -> 0 | F6: =4*F3 -> 0 | G6: =4*G3 -> 0 | H6: =4*H3 -> 0 | O6: =SUM(E6:J6) -> 0 | P6: =D6*O6 -> 0
A7: BACK PANEL 500X700 | B7: fond 500 x 700 | D7: 4.27 | E7: =1*E3 -> 0 | F7: =1*F3 -> 0 | G7: =1*G3 -> 0 | H7: =1*H3 -> 0 | O7: =SUM(E7:J7) -> 0 | P7: =D7*O7 -> 0
A8: SLIDING BACK PANEL 400X700 | B8: fond extensible 400 | D8: 6.23 | O8: =SUM(E8:J8) -> 0 | P8: =D8*O8 -> 0
A9: SLIDING BACK PANEL 500X700 | B9: Fond extensible 500 | D9: 7.658 | O9: =SUM(E9:J9) -> 0 | P9: =D9*O9 -> 0
A10: SHELF MONOBLOCK (WITHOUT C LABELS) 200X500 | B10: Tablette 200 x 500 | C10: SEPERATOR WITHOUT HOLES - FLAT separateur sans trou | D10: 2.4472 | I10: =8*I3 -> 0 | O10: =SUM(E10:J10) -> 0 | P10: =D10*O10 -> 0
A11: SHELF MONOBLOCK (WITHOUT C LABELS) 200X700 | B11: Tablette 200 x 700 | C11: SEPERATOR WITHOUT HOLES - FLAT separateur sans trou | D11: 3.38744 | G11: =8*G3 -> 0 | H11: =8*H3 -> 0 | O11: =SUM(E11:J11) -> 0 | P11: =D11*O11 -> 0
A12: SHELF MONOBLOCK (WITHOUT C LABELS) 200X700 | B12: Tablette 200 x 700 pour bacs soldeurs | C12: GLASS SEPERATOR PERFORATED perforation pour separateur verre | D12: 3.38744 | O12: =SUM(E12:J12) -> 0 | P12: =D12*O12 -> 0
A13: SHELF MONOBLOCK (WITHOUT C LABELS) 300X700 | B13: Tabette 300 x 700 pour bacs soldeurs | C13: GLASS SEPERATOR PERFORATED perforation pour separateur verre | D13: 4.0572 | O13: =SUM(E13:J13) -> 0 | P13: =D13*O13 -> 0
A14: SHELF MONOBLOCK (WITHOUT C LABELS) 400 X 700 | B14: Tabette 400 x 700 pour bacs soldeurs | C14: GLASS SEPERATOR PERFORATED perforation pour separateur verre | D14: 4.0572 | O14: =SUM(E14:J14) -> 0 | P14: =D14*O14 -> 0
A15: SHELF MONOBLOCK (WITHOUT C LABELS) 200 X 500 | B15: Tabette 200 x 500 pour bacs soldeurs | C15: GLASS SEPERATOR PERFORATED perforation pour separateur verre | D15: 4.0572 | O15: =SUM(E15:J15) -> 0 | P15: =D15*O15 -> 0
A16: SHELF MONOBLOCK (WITHOUT C LABELS) 300 X 500 | B16: Tabette 300 x 500 pour bacs soldeurs | C16: GLASS SEPERATOR PERFORATED perforation pour separateur verre | D16: 4.0572 | O16: =SUM(E16:J16) -> 0 | P16: =D16*O16 -> 0
A17: SHELF MONOBLOCK (WITHOUT C LABELS) 400 X 500 | B17: Tabette 400 x 500 pour bacs soldeurs | C17: GLASS SEPERATOR PERFORATED perforation pour separateur verre | D17: 4.0572 | O17: =SUM(E17:J17) -> 0 | P17: =D17*O17 -> 0
A18: SHELF MONOBLOCK (WITHOUT C LABELS) 300X500 | B18: Tabette 300 x 500 sans trou | C18: SEPERATOR WITHOUT HOLES - FLAT separateur sans trou | D18: 4.0572 | J18: =8*J3 -> 0 | O18: =SUM(E18:J18) -> 0 | P18: =D18*O18 -> 0
A19: SHELF MONOBLOCK (WITHOUT C LABELS) 400X500 | B19: Tabette 400 x 500 sans trou | C19: SEPERATOR WITHOUT HOLES - FLAT separateur sans trou | D19: 4.0572
A20: SHELF MONOBLOCK (WITHOUT C LABELS) 300X700 | B20: Tabette 300 x 700 sans trou | C20: SEPERATOR WITHOUT HOLES - FLAT separateur sans trou | D20: 4.0572 | E20: =8*E3 -> 0 | F20: =8*F3 -> 0 | O20: =SUM(E20:J20) -> 0 | P20: =D20*O20 -> 0
A21: SHELF MONOBLOCK (WITHOUT C LABELS) 400X700 | B21: Tablette 400 x 700 sans trou | C21: SEPERATOR WITHOUT HOLES - FLAT separateur sans trou | D21: 5.3 | O21: =SUM(E21:J21) -> 0 | P21: =D21*O21 -> 0
A22: PERFORATED SHELF MONOBLOCK (WITHOUT C LABELS) 300X700 | B22: Tablette 300 x 700 perforée | C22: STANDART PERFORATED SHELF Tablette standard perforée | D22: 5.30656 | O22: =SUM(E22:J22) -> 0 | P22: =D22*O22 -> 0
A23: PERFORATED SHELF MONOBLOCK (WITHOUT C LABELS) 400X700 | B23: TABLETTE PERFORÉE (SANS PORTE ETIQUETTE) 400 X 700 | C23: STANDART PERFORATED SHELF Tablette standard perforée | D23: 5.30656 | O23: =SUM(E23:J23) -> 0 | P23: =D23*O23 -> 0
A24: GLASS SEPERATOR APPARATUS-CORNER | B24: SEPARATEUR VERRE D'ANGLE | D24: 0.24 | O24: =SUM(E24:J24) -> 0 | P24: =D24*O24 -> 0
A25: GLASS SEPERATOR APPARATUS-FLAT | B25: SEPARATEUR VERRE PLAT | D25: 0.17 | O25: =SUM(E25:J25) -> 0 | P25: =D25*O25 -> 0
A26: SIDE GLASS SEPERATOR 200X180 , 6MM TEMPERED GLASS | B26: VERRE LATÉRAL VERRE TREMPÉ 6MM 200 X 180 | D26: 7.2 | O26: =SUM(E26:J26) -> 0 | P26: =D26*O26 -> 0
A27: SIDE GLASS SEPERATOR 300X180 , 6MM TEMPERED GLASS | B27: VERRE LATÉRAL VERRE TREMPÉ 6MM 300 X 180 | D27: 7.2 | O27: =SUM(E27:J27) -> 0 | P27: =D27*O27 -> 0
A28: SIDE GLASS SEPERATOR 400X180 , 6MM TEMPERED GLASS | B28: VERRE LATÉRAL VERRE TREMPÉ 6MM 400 X 180 | D28: 7.2 | O28: =SUM(E28:J28) -> 0 | P28: =D28*O28 -> 0
A29: FRONT WINDOW SEPERATOR L:700 H:100, 6MM TEMPERED GLASS | B29: VERRE FRONTAL VERRE TREMPÉ 6 MM 700 X 100 | D29: 7.2 | O29: =SUM(E29:J29) -> 0 | P29: =D29*O29 -> 0
A30: FRONT WINDOW SEPERATOR L:500 H:100, 6MM TEMPERED GLASS | B30: VERRE FRONTAL VERRE TREMPÉ 6 MM 500 X 100 | D30: 7.2 | O30: =SUM(E30:J30) -> 0 | P30: =D30*O30 -> 0
A31: FRONT WINDOW SEPERATOR L:500 H:100, 6MM TEMPERED GLASS | B31: VERRE FRONTAL VERRE TREMPÉ 6 MM 500 X 100 | D31: 7.2 | O31: =SUM(E31:J31) -> 0 | P31: =D31*O31 -> 0
A32: GLASS SHELF (6mm TEMPERED) 200X500 | B32: Tablette verre 200 x 500 | C32: FOR THE MIDDLE COUNTER DESK pour inter comptoir | D32: 8.792 | O32: =SUM(E32:J32) -> 0 | P32: =D32*O32 -> 0
A33: GLASS SHELF (6mm TEMPERED) 200X500 | B33: Tablettes verres 200 X 500 | C33: FOR THE WALL UNIT Pour les linéaires muraux | D33: 8.792 | O33: =SUM(E33:J33) -> 0 | P33: =D33*O33 -> 0
A34: GLASS SHELF (6mm TEMPERED) 200X700 | B34: Tablettes verres 200 X 700 | C34: FOR THE WALL UNIT Pour les linéaires muraux | D34: 9.618 | O34: =SUM(E34:J34) -> 0 | P34: =D34*O34 -> 0
A35: GLASS SHELF (6mm TEMPERED) 300X500 | B35: Tablettes verres 300 X 500 | C35: FOR THE WALL UNIT Pour les linéaires muraux | D35: 9.618 | O35: =SUM(E35:J35) -> 0 | P35: =D35*O35 -> 0
A36: GLASS SHELF (6mm TEMPERED) 300X700 | B36: Tablettes verres 300 X 700 | C36: FOR THE WALL UNIT Pour les linéaires muraux | D36: 9.618 | O36: =SUM(E36:J36) -> 0 | P36: =D36*O36 -> 0
A37: SLIDING SHELF (WITHOUT HOLES) 200X700 | B37: Tablettes extensibles sans trou 200 X 700 | C37: RAL 7201 | D37: 6.622 | O37: =SUM(E37:J37) -> 0 | P37: =D37*O37 -> 0
A38: SLIDING SHELF (WITHOUT HOLES) 300X700 | B38: Tablettes extensibles sans trou 300 X 700 | C38: RAL 7201 | D38: 6.622 | O38: =SUM(E38:J38) -> 0 | P38: =D38*O38 -> 0
A39: SLIDING SHELF (WITHOUT HOLES) 400X700 | B39: Tablettes extensibles sans trou 400 X 700 | C39: RAL 9003 | D39: 8.652 | O39: =SUM(E39:J39) -> 0 | P39: =D39*O39 -> 0
A40: GLASS SHELF CONSOLE 200X700 | B40: Console tablettes verre 200 X 700 | C40: RAL 7201 | D40: 7.22 | O40: =SUM(E40:J40) -> 0 | P40: =D40*O40 -> 0
A41: GLASS SHELF CONSOLE (ONE PIECE) 200X500 | B41: Console tablettes verre 200 X 500 | C41: RAL 7201 | D41: 5.16 | O41: =SUM(E41:J41) -> 0 | P41: =D41*O41 -> 0
...

Sheet LINÉAIRE MÉTAL Base + 8
A1: Désignation produit en anglais | B1: Désignation produit en francais | C1: remarques | D1: Prix d'achat unitaire HT | E1: LINEAIRE 2200 x 700 x 300 Métal base +8 | F1: SUITE LINEAIRE 2200 x 700 x 300 Métal base +8 | G1: LINEAIRE 2200 x 700 x 200 métal base +8 | H1: SUITE LINEAIRE 2200 x 700 x 200 métal base +8 | I1: LINEAIRE 2200 x 500 x 200 métal base +8 | J1: LINEAIRE 2200 x 500 x 300 métal base +8
D3: QUANTITÉ | E3: 0 | F3: 0 | G3: 0 | H3: 0 | I3: 0 | J3: 0 | O3: TOTAL | P3: PRIX
A4: BACK PANEL 400X500 | B4: Fond 400 x 500 | D4: 3.20712 | I4: =4*I3 -> 0 | J4: =4*J3 -> 0 | O4: =SUM(E4:J4) -> 0 | P4: =D4*O4 -> 0
A5: BACK PANEL 500X500 | B5: fond 500 x 500 | D5: 4.10872 | I5: =1*I3 -> 0 | J5: =1*J3 -> 0 | O5: =SUM(E5:J5) -> 0 | P5: =D5*O5 -> 0
A6: BACK PANEL 400X700 | B6: Fond 400 x 700 | D6: 3.47 | E6: =4*E3 -> 0 | F6: =4*F3 -> 0 | G6: =4*G3 -> 0 | H6: =4*H3 -> 0 | O6: =SUM(E6:J6) -> 0 | P6: =D6*O6 -> 0
A7: BACK PANEL 500X700 | B7: fond 500 x 700 | D7: 4.27 | E7: =1*E3 -> 0 | F7: =1*F3 -> 0 | G7: =1*G3 -> 0 | H7: =1*H3 -> 0 | O7: =SUM(E7:J7) -> 0 | P7: =D7*O7 -> 0
A8: SLIDING BACK PANEL 400X700 | B8: fond extensible 400 | D8: 6.23 | O8: =SUM(E8:J8) -> 0 | P8: =D8*O8 -> 0
A9: SLIDING BACK PANEL 500X700 | B9: Fond extensible 500 | D9: 7.658 | O9: =SUM(E9:J9) -> 0 | P9: =D9*O9 -> 0
A10: SHELF MONOBLOCK (WITHOUT C LABELS) 200X500 | B10: Tablette 200 x 500 | C10: SEPERATOR WITHOUT HOLES - FLAT separateur sans trou | D10: 2.4472 | I10: =9*I3 -> 0 | O10: =SUM(E10:J10) -> 0 | P10: =D10*O10 -> 0
A11: SHELF MONOBLOCK (WITHOUT C LABELS) 200X700 | B11: Tablette 200 x 700 | C11: SEPERATOR WITHOUT HOLES - FLAT separateur sans trou | D11: 3.38744 | G11: =9*G3 -> 0 | H11: =9*H3 -> 0 | O11: =SUM(E11:J11) -> 0 | P11: =D11*O11 -> 0
A12: SHELF MONOBLOCK (WITHOUT C LABELS) 200X700 | B12: Tablette 200 x 700 pour bacs soldeurs | C12: GLASS SEPERATOR PERFORATED perforation pour separateur verre | D12: 3.38744 | O12: =SUM(E12:J12) -> 0 | P12: =D12*O12 -> 0
A13: SHELF MONOBLOCK (WITHOUT C LABELS) 300X700 | B13: Tabette 300 x 700 pour bacs soldeurs | C13: GLASS SEPERATOR PERFORATED perforation pour separateur verre | D13: 4.0572 | O13: =SUM(E13:J13) -> 0 | P13: =D13*O13 -> 0
A14: SHELF MONOBLOCK (WITHOUT C LABELS) 400 X 700 | B14: Tabette 400 x 700 pour bacs soldeurs | C14: GLASS SEPERATOR PERFORATED perforation pour separateur verre | D14: 4.0572 | O14: =SUM(E14:J14) -> 0 | P14: =D14*O14 -> 0
A15: SHELF MONOBLOCK (WITHOUT C LABELS) 200 X 500 | B15: Tabette 200 x 500 pour bacs soldeurs | C15: GLASS SEPERATOR PERFORATED perforation pour separateur verre | D15: 4.0572 | O15: =SUM(E15:J15) -> 0 | P15: =D15*O15 -> 0
A16: SHELF MONOBLOCK (WITHOUT C LABELS) 300 X 500 | B16: Tabette 300 x 500 pour bacs soldeurs | C16: GLASS SEPERATOR PERFORATED perforation pour separateur verre | D16: 4.0572 | O16: =SUM(E16:J16) -> 0 | P16: =D16*O16 -> 0
A17: SHELF MONOBLOCK (WITHOUT C LABELS) 400 X 500 | B17: Tabette 400 x 500 pour bacs soldeurs | C17: GLASS SEPERATOR PERFORATED perforation pour separateur verre | D17: 4.0572 | O17: =SUM(E17:J17) -> 0 | P17: =D17*O17 -> 0
A18: SHELF MONOBLOCK (WITHOUT C LABELS) 300X500 | B18: Tabette 300 x 500 sans trou | C18: SEPERATOR WITHOUT HOLES - FLAT separateur sans trou | D18: 4.0572 | J18: =9*J3 -> 0 | O18: =SUM(E18:J18) -> 0 | P18: =D18*O18 -> 0
A19: SHELF MONOBLOCK (WITHOUT C LABELS) 400X500 | B19: Tabette 400 x 500 sans trou | C19: SEPERATOR WITHOUT HOLES - FLAT separateur sans trou | D19: 4.0572
A20: SHELF MONOBLOCK (WITHOUT C LABELS) 300X700 | B20: Tabette 300 x 700 sans trou | C20: SEPERATOR WITHOUT HOLES - FLAT separateur sans trou | D20: 4.0572 | E20: =9*E3 -> 0 | F20: =9*F3 -> 0 | O20: =SUM(E20:J20) -> 0 | P20: =D20*O20 -> 0
A21: PERFORATED SHELF MONOBLOCK (WITHOUT C LABELS) 400X700 | B21: Tablette 400 x 700 sans trou | C21: SEPERATOR WITHOUT HOLES - FLAT separateur sans trou | D21: 5.3 | O21: =SUM(E21:J21) -> 0 | P21: =D21*O21 -> 0
A22: PERFORATED SHELF MONOBLOCK (WITHOUT C LABELS) 300X700 | B22: Tablette 300 x 700 perforée | C22: STANDART PERFORATED SHELF Tablette standard perforée | D22: 5.30656 | O22: =SUM(E22:J22) -> 0 | P22: =D22*O22 -> 0
A23: PERFORATED SHELF MONOBLOCK (WITHOUT C LABELS) 400X700 | B23: TABLETTE PERFORÉE (SANS PORTE ETIQUETTE) 400 X 700 | C23: STANDART PERFORATED SHELF Tablette standard perforée | D23: 5.30656 | O23: =SUM(E23:J23) -> 0 | P23: =D23*O23 -> 0
A24: GLASS SEPERATOR APPARATUS-CORNER | B24: SEPARATEUR VERRE D'ANGLE | D24: 0.24 | O24: =SUM(E24:J24) -> 0 | P24: =D24*O24 -> 0
A25: GLASS SEPERATOR APPARATUS-FLAT | B25: SEPARATEUR VERRE PLAT | D25: 0.17 | O25: =SUM(E25:J25) -> 0 | P25: =D25*O25 -> 0
A26: SIDE GLASS SEPERATOR 200X180 , 6MM TEMPERED GLASS | B26: VERRE LATÉRAL VERRE TREMPÉ 6MM 200 X 180 | D26: 7.2 | O26: =SUM(E26:J26) -> 0 | P26: =D26*O26 -> 0
A27: SIDE GLASS SEPERATOR 300X180 , 6MM TEMPERED GLASS | B27: VERRE LATÉRAL VERRE TREMPÉ 6MM 300 X 180 | D27: 7.2 | O27: =SUM(E27:J27) -> 0 | P27: =D27*O27 -> 0
A28: SIDE GLASS SEPERATOR 400X180 , 6MM TEMPERED GLASS | B28: VERRE LATÉRAL VERRE TREMPÉ 6MM 400 X 180 | D28: 7.2 | O28: =SUM(E28:J28) -> 0 | P28: =D28*O28 -> 0
A29: FRONT WINDOW SEPERATOR L:700 H:100, 6MM TEMPERED GLASS | B29: VERRE FRONTAL VERRE TREMPÉ 6 MM 700 X 100 | D29: 7.2 | O29: =SUM(E29:J29) -> 0 | P29: =D29*O29 -> 0
A30: FRONT WINDOW SEPERATOR L:500 H:100, 6MM TEMPERED GLASS | B30: VERRE FRONTAL VERRE TREMPÉ 6 MM 500 X 100 | D30: 7.2 | O30: =SUM(E30:J30) -> 0 | P30: =D30*O30 -> 0
A31: FRONT WINDOW SEPERATOR L:500 H:100, 6MM TEMPERED GLASS | B31: VERRE FRONTAL VERRE TREMPÉ 6 MM 500 X 100 | D31: 7.2 | O31: =SUM(E31:J31) -> 0 | P31: =D31*O31 -> 0
A32: GLASS SHELF (6mm TEMPERED) 200X500 | B32: Tablette verre 200 x 500 | C32: FOR THE MIDDLE COUNTER DESK pour inter comptoir | D32: 8.792 | O32: =SUM(E32:J32) -> 0 | P32: =D32*O32 -> 0
A33: GLASS SHELF (6mm TEMPERED) 200X500 | B33: Tablettes verres 200 X 500 | C33: FOR THE WALL UNIT Pour les linéaires muraux | D33: 8.792 | O33: =SUM(E33:J33) -> 0 | P33: =D33*O33 -> 0
A34: GLASS SHELF (6mm TEMPERED) 200X700 | B34: Tablettes verres 200 X 700 | C34: FOR THE WALL UNIT Pour les linéaires muraux | D34: 9.618 | O34: =SUM(E34:J34) -> 0 | P34: =D34*O34 -> 0
A35: GLASS SHELF (6mm TEMPERED) 300X500 | B35: Tablettes verres 300 X 500 | C35: FOR THE WALL UNIT Pour les linéaires muraux | D35: 9.618 | O35: =SUM(E35:J35) -> 0 | P35: =D35*O35 -> 0
A36: GLASS SHELF (6mm TEMPERED) 300X700 | B36: Tablettes verres 300 X 700 | C36: FOR THE WALL UNIT Pour les linéaires muraux | D36: 9.618 | O36: =SUM(E36:J36) -> 0 | P36: =D36*O36 -> 0
A37: SLIDING SHELF (WITHOUT HOLES) 200X700 | B37: Tablettes extensibles sans trou 300 X 700 | C37: RAL 7201 | D37: 6.622 | O37: =SUM(E37:J37) -> 0 | P37: =D37*O37 -> 0
A38: SLIDING SHELF (WITHOUT HOLES) 300X700 | B38: Tablettes extensibles sans trou 300 X 700 | C38: RAL 7201 | D38: 6.622 | O38: =SUM(E38:J38) -> 0 | P38: =D38*O38 -> 0
A39: SLIDING SHELF (WITHOUT HOLES) 400X700 | B39: Tablettes extensibles sans trou 400 X 700 | C39: RAL 9003 | D39: 8.652 | O39: =SUM(E39:J39) -> 0 | P39: =D39*O39 -> 0
A40: GLASS SHELF CONSOLE 200X700 | B40: Console tablettes verre 200 X 700 | C40: RAL 7201 | D40: 7.22 | O40: =SUM(E40:J40) -> 0 | P40: =D40*O40 -> 0
A41: GLASS SHELF CONSOLE (ONE PIECE) 200X500 | B41: Console tablettes verre 200 X 500 | C41: RAL 7201 | D41: 5.16 | O41: =SUM(E41:J41) -> 0 | P41: =D41*O41 -> 0
...

Sheet LINÉAIRE MÉTAL Base + 9
A1: Désignation produit en anglais | B1: Désignation produit en francais | C1: remarques | D1: Prix d'achat unitaire HT | E1: LINEAIRE 2200 x 700 x 300 Métal base + 9 | F1: SUITE LINEAIRE 2200 x 700 x 300 Métal base + 9 | G1: LINEAIRE 2200 x 700 x 200 métal base + 9 | H1: SUITE LINEAIRE 2200 x 700 x 200 métal base + 9 | I1: LINEAIRE 2200 x 500 x 200 métal base + 9 | J1: LINEAIRE 2200 x 500 x 300 métal base + 9
D3: QUANTITÉ | E3: 0 | F3: 0 | G3: 0 | H3: 0 | I3: 0 | J3: 0 | O3: TOTAL | P3: PRIX
A4: BACK PANEL 400X500 | B4: Fond 400 x 500 | D4: 3.20712 | I4: =4*I3 -> 0 | J4: =4*J3 -> 0 | O4: =SUM(E4:J4) -> 0 | P4: =D4*O4 -> 0
A5: BACK PANEL 500X500 | B5: fond 500 x 500 | D5: 4.10872 | I5: =1*I3 -> 0 | J5: =1*J3 -> 0 | O5: =SUM(E5:J5) -> 0 | P5: =D5*O5 -> 0
A6: BACK PANEL 400X700 | B6: Fond 400 x 700 | D6: 3.47 | E6: =4*E3 -> 0 | F6: =4*F3 -> 0 | G6: =4*G3 -> 0 | H6: =4*H3 -> 0 | O6: =SUM(E6:J6) -> 0 | P6: =D6*O6 -> 0
A7: BACK PANEL 500X700 | B7: fond 500 x 700 | D7: 4.27 | E7: =1*E3 -> 0 | F7: =1*F3 -> 0 | G7: =1*G3 -> 0 | H7: =1*H3 -> 0 | O7: =SUM(E7:J7) -> 0 | P7: =D7*O7 -> 0
A8: SLIDING BACK PANEL 400X700 | B8: fond extensible 400 | D8: 6.23 | G8: 0 | O8: =SUM(E8:J8) -> 0 | P8: =D8*O8 -> 0
A9: SLIDING BACK PANEL 500X700 | B9: Fond extensible 500 | D9: 7.658 | O9: =SUM(E9:J9) -> 0 | P9: =D9*O9 -> 0
A10: SHELF MONOBLOCK 200X500 | B10: Tablette 200 x 500 | C10: SEPERATOR WITHOUT HOLES - FLAT separateur sans trou | D10: 2.4472 | I10: =10*I3 -> 0 | O10: =SUM(E10:J10) -> 0 | P10: =D10*O10 -> 0
A11: SHELF MONOBLOCK 200X700 | B11: Tablette 200 x 700 | C11: SEPERATOR WITHOUT HOLES - FLAT separateur sans trou | D11: 3.38744 | G11: =10*G3 -> 0 | H11: =10*H3 -> 0 | O11: =SUM(E11:J11) -> 0 | P11: =D11*O11 -> 0
A12: SHELF MONOBLOCK 200X700 | B12: Tablette 200 x 700 pour bacs soldeurs | C12: GLASS SEPERATOR PERFORATED perforation pour separateur verre | D12: 3.38744 | O12: =SUM(E12:J12) -> 0 | P12: =D12*O12 -> 0
A13: SHELF MONOBLOCK 300X700 | B13: Tabette 300 x 700 pour bacs soldeurs | C13: GLASS SEPERATOR PERFORATED perforation pour separateur verre | D13: 4.0572 | O13: =SUM(E13:J13) -> 0 | P13: =D13*O13 -> 0
A14: SHELF MONOBLOCK (WITHOUT C LABELS) 400 X 700 | B14: Tabette 400 x 700 pour bacs soldeurs | C14: GLASS SEPERATOR PERFORATED perforation pour separateur verre | D14: 4.0572 | O14: =SUM(E14:J14) -> 0 | P14: =D14*O14 -> 0
A15: SHELF MONOBLOCK (WITHOUT C LABELS) 200 X 500 | B15: Tabette 200 x 500 pour bacs soldeurs | C15: GLASS SEPERATOR PERFORATED perforation pour separateur verre | D15: 4.0572 | O15: =SUM(E15:J15) -> 0 | P15: =D15*O15 -> 0
A16: SHELF MONOBLOCK (WITHOUT C LABELS) 300 X 500 | B16: Tabette 300 x 500 pour bacs soldeurs | C16: GLASS SEPERATOR PERFORATED perforation pour separateur verre | D16: 4.0572 | O16: =SUM(E16:J16) -> 0 | P16: =D16*O16 -> 0
A17: SHELF MONOBLOCK (WITHOUT C LABELS) 400 X 500 | B17: Tabette 400 x 500 pour bacs soldeurs | C17: GLASS SEPERATOR PERFORATED perforation pour separateur verre | D17: 4.0572 | O17: =SUM(E17:J17) -> 0 | P17: =D17*O17 -> 0
A18: SHELF MONOBLOCK 300X500 | B18: Tabette 300 x 500 sans trou | C18: SEPERATOR WITHOUT HOLES - FLAT separateur sans trou | D18: 4.0572 | J18: =10*J3 -> 0 | O18: =SUM(E18:J18) -> 0 | P18: =D18*O18 -> 0
A19: SHELF MONOBLOCK (WITHOUT C LABELS) 400X500 | B19: Tabette 400 x 500 sans trou | C19: SEPERATOR WITHOUT HOLES - FLAT separateur sans trou | D19: 4.0572 | O19: =SUM(E19:J19) -> 0
A20: SHELF MONOBLOCK 300X700 | B20: Tabette 300 x 700 sans trou | C20: SEPERATOR WITHOUT HOLES - FLAT separateur sans trou | D20: 4.0572 | E20: =10*E3 -> 0 | F20: =10*F3 -> 0 | O20: =SUM(E20:J20) -> 0 | P20: =D20*O20 -> 0
A21: SHELF MONOBLOCK 400X700 | B21: Tablette 400 x 700 sans trou | C21: SEPERATOR WITHOUT HOLES - FLAT separateur sans trou | D21: 5.3 | O21: =SUM(E21:J21) -> 0 | P21: =D21*O21 -> 0
A22: PERFORATED SHELF MONOBLOCK (WITHOUT C LABELS) 300X700 | B22: Tablette 300 x 700 perforée | C22: STANDART PERFORATED SHELF Tablette standard perforée | D22: 5.30656 | O22: =SUM(E22:J22) -> 0 | P22: =D22*O22 -> 0
A23: PERFORATED SHELF MONOBLOCK (WITHOUT C LABELS) 400X700 | B23: TABLETTE PERFORÉE (SANS PORTE ETIQUETTE) 400 X 700 | C23: STANDART PERFORATED SHELF Tablette standard perforée | D23: 5.30656 | O23: =SUM(E23:J23) -> 0 | P23: =D23*O23 -> 0
A24: GLASS SEPERATOR APPARATUS-CORNER | B24: SEPARATEUR VERRE D'ANGLE | D24: 0.24 | O24: =SUM(E24:J24) -> 0 | P24: =D24*O24 -> 0
A25: GLASS SEPERATOR APPARATUS-FLAT | B25: SEPARATEUR VERRE PLAT | D25: 0.17 | O25: =SUM(E25:J25) -> 0 | P25: =D25*O25 -> 0
A26: SIDE GLASS SEPERATOR 200X180 , 6MM TEMPERED GLASS | B26: VERRE LATÉRAL VERRE TREMPÉ 6MM 200 X 180 | D26: 7.2 | O26: =SUM(E26:J26) -> 0 | P26: =D26*O26 -> 0
A27: SIDE GLASS SEPERATOR 300X180 , 6MM TEMPERED GLASS | B27: VERRE LATÉRAL VERRE TREMPÉ 6MM 300 X 180 | D27: 7.2 | O27: =SUM(E27:J27) -> 0 | P27: =D27*O27 -> 0
A28: SIDE GLASS SEPERATOR 400X180 , 6MM TEMPERED GLASS | B28: VERRE LATÉRAL VERRE TREMPÉ 6MM 400 X 180 | D28: 7.2 | O28: =SUM(E28:J28) -> 0 | P28: =D28*O28 -> 0
A29: FRONT WINDOW SEPERATOR L:700 H:100, 6MM TEMPERED GLASS | B29: VERRE FRONTAL VERRE TREMPÉ 6 MM 700 X 100 | D29: 7.2 | O29: =SUM(E29:J29) -> 0 | P29: =D29*O29 -> 0
A30: FRONT WINDOW SEPERATOR L:500 H:100, 6MM TEMPERED GLASS | B30: VERRE FRONTAL VERRE TREMPÉ 6 MM 500 X 100 | D30: 7.2 | O30: =SUM(E30:J30) -> 0 | P30: =D30*O30 -> 0
A31: FRONT WINDOW SEPERATOR L:500 H:100, 6MM TEMPERED GLASS | B31: VERRE FRONTAL VERRE TREMPÉ 6 MM 500 X 100 | D31: 7.2 | O31: =SUM(E31:J31) -> 0 | P31: =D31*O31 -> 0
A32: GLASS SHELF (6mm TEMPERED) 200X500 | B32: Tablette verre 200 x 500 | C32: FOR THE MIDDLE COUNTER DESK pour inter comptoir | D32: 8.792 | O32: =SUM(E32:J32) -> 0 | P32: =D32*O32 -> 0
A33: GLASS SHELF (6mm TEMPERED) 200X500 | B33: Tablettes verres 200 X 500 | C33: FOR THE WALL UNIT Pour les linéaires muraux | D33: 8.792 | O33: =SUM(E33:J33) -> 0 | P33: =D33*O33 -> 0
A34: GLASS SHELF (6mm TEMPERED) 200X700 | B34: Tablettes verres 200 X 700 | C34: FOR THE WALL UNIT Pour les linéaires muraux | D34: 9.618 | O34: =SUM(E34:J34) -> 0 | P34: =D34*O34 -> 0
A35: GLASS SHELF (6mm TEMPERED) 300X500 | B35: Tablettes verres 300 X 500 | C35: FOR THE WALL UNIT Pour les linéaires muraux | D35: 9.618 | O35: =SUM(E35:J35) -> 0 | P35: =D35*O35 -> 0
A36: GLASS SHELF (6mm TEMPERED) 300X700 | B36: Tablettes verres 300 X 700 | C36: FOR THE WALL UNIT Pour les linéaires muraux | D36: 9.618 | O36: =SUM(E36:J36) -> 0 | P36: =D36*O36 -> 0
A37: SLIDING SHELF (WITHOUT HOLES) 200X700 | B37: Tablettes extensibles sans trou 200 X 700 | C37: RAL 7201 | D37: 6.622 | O37: =SUM(E37:J37) -> 0 | P37: =D37*O37 -> 0
A38: SLIDING SHELF (WITHOUT HOLES) 300X700 | B38: Tablettes extensibles sans trou 300 X 700 | C38: RAL 7201 | D38: 6.622 | O38: =SUM(E38:J38) -> 0 | P38: =D38*O38 -> 0
A39: SLIDING SHELF (WITHOUT HOLES) 400X700 | B39: Tablettes extensibles sans trou 400 X 700 | C39: RAL 9003 | D39: 8.652 | O39: =SUM(E39:J39) -> 0 | P39: =D39*O39 -> 0
A40: GLASS SHELF CONSOLE 200X700 | B40: Console tablettes verre 200 X 700 | C40: RAL 7201 | D40: 7.22 | O40: =SUM(E40:J40) -> 0 | P40: =D40*O40 -> 0
A41: GLASS SHELF CONSOLE (ONE PIECE) 200X500 | B41: Console tablettes verre 200 X 500 | C41: RAL 7201 | D41: 5.16 | O41: =SUM(E41:J41) -> 0 | P41: =D41*O41 -> 0
...

Sheet EXTENSIBLES
A1: Désignation produit en anglais | B1: Désignation produit en francais | C1: remarques | D1: Prix d'achat unitaire HT | E1: LINEAIRE EXTENSIBLE 2200 x 400 Métal base + K | F1: LINEAIRE EXTENSIBLE 2200 x 300 Métal base + K | G1: LINEAIRE EXTENSIBLE 2200 x 200 métal base + K
D2: K | E2: 0 | F2: 0 | G2: 0
D3: QUANTITÉ | E3: 0 | F3: 0 | G3: 0 | O3: TOTAL | P3: PRIX
A4: BACK PANEL 400X500 | B4: Fond 400 x 500 | D4: 3.20712 | O4: =SUM(E4:G4) -> 0 | P4: =D4*O4 -> 0
A5: BACK PANEL 500X500 | B5: fond 500 x 500 | D5: 4.10872 | O5: =SUM(E5:G5) -> 0 | P5: =D5*O5 -> 0
A6: BACK PANEL 400X700 | B6: Fond 400 x 700 | D6: 3.47 | O6: =SUM(E6:G6) -> 0 | P6: =D6*O6 -> 0
A7: BACK PANEL 500X700 | B7: fond 500 x 700 | D7: 4.27 | O7: =SUM(E7:G7) -> 0 | P7: =D7*O7 -> 0
A8: SLIDING BACK PANEL 400X700 | B8: fond extensible 400 | D8: 6.23 | E8: =4*E3 -> 0 | F8: =4*F3 -> 0 | G8: =4*G3 -> 0 | O8: =SUM(E8:G8) -> 0 | P8: =D8*O8 -> 0
A9: SLIDING BACK PANEL 500X700 | B9: Fond extensible 500 | D9: 7.658 | E9: =1*E3 -> 0 | F9: =1*F3 -> 0 | G9: =1*G3 -> 0 | O9: =SUM(E9:G9) -> 0 | P9: =D9*O9 -> 0
A10: SHELF MONOBLOCK 200X500 | B10: Tablette 200 x 500 | C10: SEPERATOR WITHOUT HOLES - FLAT separateur sans trou | D10: 2.4472 | O10: =SUM(E10:G10) -> 0 | P10: =D10*O10 -> 0
A11: SHELF MONOBLOCK 200X700 | B11: Tablette 200 x 700 | C11: SEPERATOR WITHOUT HOLES - FLAT separateur sans trou | D11: 3.38744 | O11: =SUM(E11:G11) -> 0 | P11: =D11*O11 -> 0
A12: SHELF MONOBLOCK (WITHOUT C LABELS) 200X700 | B12: Tablette 200 x 700 pour bacs soldeurs | C12: GLASS SEPERATOR PERFORATED perforation pour separateur verre | D12: 3.38744 | O12: =SUM(E12:G12) -> 0 | P12: =D12*O12 -> 0
A13: SHELF MONOBLOCK (WITHOUT C LABELS) 300X700 | B13: Tabette 300 x 700 pour bacs soldeurs | C13: GLASS SEPERATOR PERFORATED perforation pour separateur verre | D13: 4.0572 | O13: =SUM(E13:G13) -> 0 | P13: =D13*O13 -> 0
A14: SHELF MONOBLOCK (WITHOUT C LABELS) 400 X 700 | B14: Tabette 400 x 700 pour bacs soldeurs | C14: GLASS SEPERATOR PERFORATED perforation pour separateur verre | D14: 4.0572 | O14: =SUM(E14:G14) -> 0 | P14: =D14*O14 -> 0
A15: SHELF MONOBLOCK (WITHOUT C LABELS) 200 X 500 | B15: Tabette 200 x 500 pour bacs soldeurs | C15: GLASS SEPERATOR PERFORATED perforation pour separateur verre | D15: 4.0572 | O15: =SUM(E15:G15) -> 0 | P15: =D15*O15 -> 0
A16: SHELF MONOBLOCK (WITHOUT C LABELS) 300 X 500 | B16: Tabette 300 x 500 pour bacs soldeurs | C16: GLASS SEPERATOR PERFORATED perforation pour separateur verre | D16: 4.0572 | O16: =SUM(E16:G16) -> 0 | P16: =D16*O16 -> 0
A17: SHELF MONOBLOCK (WITHOUT C LABELS) 400 X 500 | B17: Tabette 400 x 500 pour bacs soldeurs | C17: GLASS SEPERATOR PERFORATED perforation pour separateur verre | D17: 4.0572 | O17: =SUM(E17:G17) -> 0 | P17: =D17*O17 -> 0
A18: SHELF MONOBLOCK (WITHOUT C LABELS) 300X500 | B18: Tabette 300 x 500 sans trou | C18: SEPERATOR WITHOUT HOLES - FLAT separateur sans trou | D18: 4.0572 | O18: =SUM(E18:G18) -> 0 | P18: =D18*O18 -> 0
A19: SHELF MONOBLOCK (WITHOUT C LABELS) 400X500 | B19: Tabette 400 x 500 sans trou | C19: SEPERATOR WITHOUT HOLES - FLAT separateur sans trou | D19: 4.0572
A20: SHELF MONOBLOCK (WITHOUT C LABELS) 300X700 | B20: Tabette 300 x 700 sans trou | C20: SEPERATOR WITHOUT HOLES - FLAT separateur sans trou | D20: 4.0572 | O20: =SUM(E20:G20) -> 0 | P20: =D20*O20 -> 0
A21: SHELF MONOBLOCK (WITHOUT C LABELS) 400X700 | B21: Tablette 400 x 700 sans trou | C21: SEPERATOR WITHOUT HOLES - FLAT separateur sans trou | D21: 5.3 | O21: =SUM(E21:G21) -> 0 | P21: =D21*O21 -> 0
A22: PERFORATED SHELF MONOBLOCK (WITHOUT C LABELS) 300X700 | B22: Tablette 300 x 700 perforée | C22: STANDART PERFORATED SHELF Tablette standard perforée | D22: 5.30656 | O22: =SUM(E22:G22) -> 0 | P22: =D22*O22 -> 0
A23: PERFORATED SHELF MONOBLOCK (WITHOUT C LABELS) 400X700 | B23: TABLETTE PERFORÉE (SANS PORTE ETIQUETTE) 400 X 700 | C23: STANDART PERFORATED SHELF Tablette standard perforée | D23: 5.30656 | O23: =SUM(E23:G23) -> 0 | P23: =D23*O23 -> 0
A24: GLASS SEPERATOR APPARATUS-CORNER | B24: SEPARATEUR VERRE D'ANGLE | D24: 0.24 | O24: =SUM(E24:G24) -> 0 | P24: =D24*O24 -> 0
A25: GLASS SEPERATOR APPARATUS-FLAT | B25: SEPARATEUR VERRE PLAT | D25: 0.17 | O25: =SUM(E25:G25) -> 0 | P25: =D25*O25 -> 0
A26: SIDE GLASS SEPERATOR 200X180 , 6MM TEMPERED GLASS | B26: VERRE LATÉRAL VERRE TREMPÉ 6MM 200 X 180 | D26: 7.2 | O26: =SUM(E26:G26) -> 0 | P26: =D26*O26 -> 0
A27: SIDE GLASS SEPERATOR 300X180 , 6MM TEMPERED GLASS | B27: VERRE LATÉRAL VERRE TREMPÉ 6MM 300 X 180 | D27: 7.2 | O27: =SUM(E27:G27) -> 0 | P27: =D27*O27 -> 0
A28: SIDE GLASS SEPERATOR 400X180 , 6MM TEMPERED GLASS | B28: VERRE LATÉRAL VERRE TREMPÉ 6MM 400 X 180 | D28: 7.2 | O28: =SUM(E28:G28) -> 0 | P28: =D28*O28 -> 0
A29: FRONT WINDOW SEPERATOR L:700 H:100, 6MM TEMPERED GLASS | B29: VERRE FRONTAL VERRE TREMPÉ 6 MM 700 X 100 | D29: 7.2 | O29: =SUM(E29:G29) -> 0 | P29: =D29*O29 -> 0
A30: FRONT WINDOW SEPERATOR L:500 H:100, 6MM TEMPERED GLASS | B30: VERRE FRONTAL VERRE TREMPÉ 6 MM 500 X 100 | D30: 7.2 | O30: =SUM(E30:G30) -> 0 | P30: =D30*O30 -> 0
A31: FRONT WINDOW SEPERATOR L:500 H:100, 6MM TEMPERED GLASS | B31: VERRE FRONTAL VERRE TREMPÉ 6 MM 500 X 100 | D31: 7.2 | O31: =SUM(E31:G31) -> 0 | P31: =D31*O31 -> 0
A32: GLASS SHELF (6mm TEMPERED) 200X500 | B32: Tablette verre 200 x 500 | C32: FOR THE MIDDLE COUNTER DESK pour inter comptoir | D32: 8.792 | O32: =SUM(E32:G32) -> 0 | P32: =D32*O32 -> 0
A33: GLASS SHELF (6mm TEMPERED) 200X500 | B33: Tablettes verres 200 X 500 | C33: FOR THE WALL UNIT Pour les linéaires muraux | D33: 8.792 | O33: =SUM(E33:G33) -> 0 | P33: =D33*O33 -> 0
A34: GLASS SHELF (6mm TEMPERED) 200X700 | B34: Tablettes verres 200 X 700 | C34: FOR THE WALL UNIT Pour les linéaires muraux | D34: 9.618 | O34: =SUM(E34:G34) -> 0 | P34: =D34*O34 -> 0
A35: GLASS SHELF (6mm TEMPERED) 300X500 | B35: Tablettes verres 300 X 500 | C35: FOR THE WALL UNIT Pour les linéaires muraux | D35: 9.618 | O35: =SUM(E35:G35) -> 0 | P35: =D35*O35 -> 0
A36: GLASS SHELF (6mm TEMPERED) 300X700 | B36: Tablettes verres 300 X 700 | C36: FOR THE WALL UNIT Pour les linéaires muraux | D36: 9.618 | O36: =SUM(E36:G36) -> 0 | P36: =D36*O36 -> 0
A37: SLIDING SHELF (WITHOUT HOLES) 200X700 | B37: Tablettes extensibles sans trou 200 | C37: RAL 7021 | D37: 6.622 | G37: =(1*G2+1)*G3 -> 0 | O37: =SUM(E37:G37) -> 0 | P37: =D37*O37 -> 0
A38: SLIDING SHELF (WITHOUT HOLES) 300X700 | B38: Tablettes extensibles sans trou 300 | C38: RAL 7021 | D38: 6.622 | F38: =(1*F2 +1)*F3 -> 0 | O38: =SUM(E38:G38) -> 0 | P38: =D38*O38 -> 0
A39: SLIDING SHELF (WITHOUT HOLES) 400X700 | B39: Tablettes extensibles sans trou 400 | C39: RAL 7021 | D39: 8.652 | E39: =(1*E2 +1)*E3 -> 0 | O39: =SUM(E39:G39) -> 0 | P39: =D39*O39 -> 0
A40: GLASS SHELF CONSOLE 200X700 | B40: Console tablettes verre 200 X 700 | C40: RAL 7021 | D40: 7.22 | O40: =SUM(E40:G40) -> 0 | P40: =D40*O40 -> 0
...

Sheet EXTENSIBLE GONDOLE SIMPLE  
A1: Désignation produit en anglais | B1: Désignation produit en francais | C1: remarques | D1: Prix d'achat unitaire HT | E1: GONDOLE SIMPLE BASE + 6 1400 X 700 X 300 | F1: GONDOLE SIMPLE BASE + 6 1400 X 700 X 200 | G1: GONDOLE SIMPLE BASE + 7 1600 X 700 X 300 | H1: GONDOLE SIMPLE BASE + 7 1600 X 700 X 200 | I1: GONDOLE SIMPLE BASE + 8 1800 X 700 X 400 | J1: GONDOLE SIMPLE BASE + 8 1800 X 700 X 300
D3: QUANTITÉ | E3: 0 | F3: 0 | G3: 0 | H3: 0 | I3: 0 | J3: 0 | O3: TOTAL | P3: PRIX
A4: BACK PANEL 400X500 | B4: Fond 400 x 500 | D4: 3.20712 | O4: =SUM(E4:J4) -> 0 | P4: =D4*O4 -> 0
A5: BACK PANEL 500X500 | B5: fond 500 x 500 | D5: 4.10872 | O5: =SUM(E5:J5) -> 0 | P5: =D5*O5 -> 0
A6: BACK PANEL 400X700 | B6: Fond 400 x 700 | D6: 3.47 | O6: =SUM(E6:J6) -> 0 | P6: =D6*O6 -> 0
A7: BACK PANEL 500X700 | B7: fond 500 x 700 | D7: 4.27 | O7: =SUM(E7:J7) -> 0 | P7: =D7*O7 -> 0
A8: SLIDING BACK PANEL 400X700 | B8: fond extensible 400 | D8: 6.23 | E8: =4*E3 -> 0 | F8: =4*F3 -> 0 | I8: =6*I3 -> 0 | J8: =6*J3 -> 0 | O8: =SUM(E8:J8) -> 0 | P8: =D8*O8 -> 0
A9: SLIDING BACK PANEL 500X700 | B9: Fond extensible 500 | D9: 7.658 | E9: =2*E3 -> 0 | F9: =2*F3 -> 0 | G9: =6*G3 -> 0 | H9: =6*H3 -> 0 | I9: =2*I3 -> 0 | J9: =2*J3 -> 0 | O9: =SUM(E9:J9) -> 0 | P9: =D9*O9 -> 0
A10: SHELF MONOBLOCK (WITHOUT C LABELS) 200X500 | B10: Tablette 200 x 500 | C10: SEPERATOR WITHOUT HOLES - FLAT separateur sans trou | D10: 2.4472 | O10: =SUM(E10:J10) -> 0 | P10: =D10*O10 -> 0
A11: SHELF MONOBLOCK (WITHOUT C LABELS) 200X700 | B11: Tablette 200 x 700 | C11: SEPERATOR WITHOUT HOLES - FLAT separateur sans trou | D11: 3.38744 | H11: =8*H3 -> 0 | O11: =SUM(E11:J11) -> 0 | P11: =D11*O11 -> 0
A12: SHELF MONOBLOCK (WITHOUT C LABELS) 200X700 | B12: Tablette 200 x 700 pour bacs soldeurs | C12: GLASS SEPERATOR PERFORATED perforation pour separateur verre | D12: 3.38744 | O12: =SUM(E12:J12) -> 0 | P12: =D12*O12 -> 0
A13: SHELF MONOBLOCK (WITHOUT C LABELS) 300X700 | B13: Tabette 300 x 700 pour bacs soldeurs | C13: GLASS SEPERATOR PERFORATED perforation pour separateur verre | D13: 4.0572 | O13: =SUM(E13:J13) -> 0 | P13: =D13*O13 -> 0
A14: SHELF MONOBLOCK (WITHOUT C LABELS) 400 X 700 | B14: Tabette 400 x 700 pour bacs soldeurs | C14: GLASS SEPERATOR PERFORATED perforation pour separateur verre | D14: 4.0572 | O14: =SUM(E14:J14) -> 0 | P14: =D14*O14 -> 0
A15: SHELF MONOBLOCK (WITHOUT C LABELS) 200 X 500 | B15: Tabette 200 x 500 pour bacs soldeurs | C15: GLASS SEPERATOR PERFORATED perforation pour separateur verre | D15: 4.0572 | O15: =SUM(E15:J15) -> 0 | P15: =D15*O15 -> 0
A16: SHELF MONOBLOCK (WITHOUT C LABELS) 300 X 500 | B16: Tabette 300 x 500 pour bacs soldeurs | C16: GLASS SEPERATOR PERFORATED perforation pour separateur verre | D16: 4.0572 | O16: =SUM(E16:J16) -> 0 | P16: =D16*O16 -> 0
A17: SHELF MONOBLOCK (WITHOUT C LABELS) 400 X 500 | B17: Tabette 400 x 500 pour bacs soldeurs | C17: GLASS SEPERATOR PERFORATED perforation pour separateur verre | D17: 4.0572 | O17: =SUM(E17:J17) -> 0 | P17: =D17*O17 -> 0
A18: SHELF MONOBLOCK (WITHOUT C LABELS) 300X500 | B18: Tabette 300 x 500 sans trou | C18: SEPERATOR WITHOUT HOLES - FLAT separateur sans trou | D18: 4.0572 | O18: =SUM(E18:J18) -> 0 | P18: =D18*O18 -> 0
A19: SHELF MONOBLOCK (WITHOUT C LABELS) 400X500 | B19: Tabette 400 x 500 sans trou | C19: SEPERATOR WITHOUT HOLES - FLAT separateur sans trou | D19: 4.0572 | O19: =SUM(E19:J19) -> 0 | P19: =D19*O19 -> 0
A20: SHELF MONOBLOCK (WITHOUT C LABELS) 300X700 | B20: Tabette 300 x 700 sans trou | C20: SEPERATOR WITHOUT HOLES - FLAT separateur sans trou | D20: 4.0572 | O20: =SUM(E20:J20) -> 0 | P20: =D20*O20 -> 0
A21: PERFORATED SHELF MONOBLOCK (WITHOUT C LABELS) 400X700 | B21: Tablette 400 x 700 sans trou | C21: SEPERATOR WITHOUT HOLES - FLAT separateur sans trou | D21: 5.3 | O21: =SUM(E21:J21) -> 0 | P21: =D21*O21 -> 0
A22: PERFORATED SHELF MONOBLOCK (WITHOUT C LABELS) 300X700 | B22: Tablette 300 x 700 perforée | C22: STANDART PERFORATED SHELF Tablette standard perforée | D22: 5.30656 | O22: =SUM(E22:J22) -> 0 | P22: =D22*O22 -> 0
A23: PERFORATED SHELF MONOBLOCK (WITHOUT C LABELS) 400X700 | B23: TABLETTE PERFORÉE (SANS PORTE ETIQUETTE) 400 X 700 | C23: STANDART PERFORATED SHELF Tablette standard perforée | D23: 5.30656 | O23: =SUM(E23:J23) -> 0 | P23: =D23*O23 -> 0
A24: GLASS SEPERATOR APPARATUS-CORNER | B24: SEPARATEUR VERRE D'ANGLE | D24: 0.24 | O24: =SUM(E24:J24) -> 0 | P24: =D24*O24 -> 0
A25: GLASS SEPERATOR APPARATUS-FLAT | B25: SEPARATEUR VERRE PLAT | D25: 0.17 | O25: =SUM(E25:J25) -> 0 | P25: =D25*O25 -> 0
A26: SIDE GLASS SEPERATOR 200X180 , 6MM TEMPERED GLASS | B26: VERRE LATÉRAL VERRE TREMPÉ 6MM 200 X 180 | D26: 7.2 | O26: =SUM(E26:J26) -> 0 | P26: =D26*O26 -> 0
A27: SIDE GLASS SEPERATOR 300X180 , 6MM TEMPERED GLASS | B27: VERRE LATÉRAL VERRE TREMPÉ 6MM 300 X 180 | D27: 7.2 | O27: =SUM(E27:J27) -> 0 | P27: =D27*O27 -> 0
A28: SIDE GLASS SEPERATOR 400X180 , 6MM TEMPERED GLASS | B28: VERRE LATÉRAL VERRE TREMPÉ 6MM 400 X 180 | D28: 7.2 | O28: =SUM(E28:J28) -> 0 | P28: =D28*O28 -> 0
A29: FRONT WINDOW SEPERATOR L:700 H:100, 6MM TEMPERED GLASS | B29: VERRE FRONTAL VERRE TREMPÉ 6 MM 700 X 100 | D29: 7.2 | O29: =SUM(E29:J29) -> 0 | P29: =D29*O29 -> 0
A30: FRONT WINDOW SEPERATOR L:500 H:100, 6MM TEMPERED GLASS | B30: VERRE FRONTAL VERRE TREMPÉ 6 MM 500 X 100 | D30: 7.2 | O30: =SUM(E30:J30) -> 0 | P30: =D30*O30 -> 0
A31: FRONT WINDOW SEPERATOR L:500 H:100, 6MM TEMPERED GLASS | B31: VERRE FRONTAL VERRE TREMPÉ 6 MM 500 X 100 | D31: 7.2 | O31: =SUM(E31:J31) -> 0 | P31: =D31*O31 -> 0
A32: GLASS SHELF (6mm TEMPERED) 200X500 | B32: Tablette verre 200 x 500 | C32: FOR THE MIDDLE COUNTER DESK pour inter comptoir | D32: 8.792 | O32: =SUM(E32:J32) -> 0 | P32: =D32*O32 -> 0
A33: GLASS SHELF (6mm TEMPERED) 200X500 | B33: Tablettes verres 200 X 500 | C33: FOR THE WALL UNIT Pour les linéaires muraux | D33: 8.792 | O33: =SUM(E33:J33) -> 0 | P33: =D33*O33 -> 0
A34: GLASS SHELF (6mm TEMPERED) 200X700 | B34: Tablettes verres 200 X 700 | C34: FOR THE WALL UNIT Pour les linéaires muraux | D34: 9.618 | O34: =SUM(E34:J34) -> 0 | P34: =D34*O34 -> 0
A35: GLASS SHELF (6mm TEMPERED) 300X500 | B35: Tablettes verres 300 X 500 | C35: FOR THE WALL UNIT Pour les linéaires muraux | D35: 9.618 | O35: =SUM(E35:J35) -> 0 | P35: =D35*O35 -> 0
A36: GLASS SHELF (6mm TEMPERED) 300X700 | B36: Tablettes verres 300 X 700 | C36: FOR THE WALL UNIT Pour les linéaires muraux | D36: 9.618 | O36: =SUM(E36:J36) -> 0 | P36: =D36*O36 -> 0
A37: SLIDING SHELF (WITHOUT HOLES) 200X700 | B37: Tablettes extensibles sans trou 300 X 700 | C37: RAL 7201 | D37: 6.622 | F37: =7*F3 -> 0 | H37: =8*H3 -> 0 | O37: =SUM(E37:J37) -> 0 | P37: =D37*O37 -> 0
A38: SLIDING SHELF (WITHOUT HOLES) 300X700 | B38: Tablettes extensibles sans trou 300 X 700 | C38: RAL 7201 | D38: 6.622 | E38: =7*E3 -> 0 | G38: =8*G3 -> 0 | J38: =9*J3 -> 0 | O38: =SUM(E38:J38) -> 0 | P38: =D38*O38 -> 0
A39: SLIDING SHELF (WITHOUT HOLES) 400X700 | B39: Tablettes extensibles sans trou 400 X 700 | C39: RAL 9003 | D39: 8.652 | I39: =9*I3 -> 0 | O39: =SUM(E39:J39) -> 0 | P39: =D39*O39 -> 0
A40: GLASS SHELF CONSOLE 200X700 | B40: Console tablettes verre 200 X 700 | C40: RAL 7201 | D40: 7.22 | O40: =SUM(E40:J40) -> 0 | P40: =D40*O40 -> 0
A41: GLASS SHELF CONSOLE (ONE PIECE) 200X500 | B41: Console tablettes verre 200 X 500 | C41: RAL 7201 | D41: 5.16 | O41: =SUM(E41:J41) -> 0 | P41: =D41*O41 -> 0
...

Sheet BACS SOLDEURS
A1: Désignation produit en anglais | B1: Désignation produit en francais | C1: remarques | D1: Prix d'achat unitaire HT | E1: BAC SOLDEUR 700 X 400 | F1: BAC SOLDEUR 700 X 300 | G1: BAC SOLDEUR 700 X 200 | H1: BAC SOLDEUR 500 X 400 | I1: BAC SOLDEUR 500 X 300 | J1: BAC SOLDEUR 500 X 200
D3: QUANTITÉ | E3: 0 | F3: 0 | G3: 0 | H3: 0 | I3: 0 | J3: 0 | O3: TOTAL | P3: PRIX
A4: BACK PANEL 400X500 | B4: Fond 400 x 500 | D4: 3.20712 | O4: =SUM(E4:J4) -> 0 | P4: =D4*O4 -> 0
A5: BACK PANEL 500X500 | B5: fond 500 x 500 | D5: 4.10872 | O5: =SUM(E5:J5) -> 0 | P5: =D5*O5 -> 0
A6: BACK PANEL 400X700 | B6: Fond 400 x 700 | D6: 3.47 | O6: =SUM(E6:J6) -> 0 | P6: =D6*O6 -> 0
A7: BACK PANEL 500X700 | B7: fond 500 x 700 | D7: 4.27 | O7: =SUM(E7:J7) -> 0 | P7: =D7*O7 -> 0
A8: SLIDING BACK PANEL 400X700 | B8: fond extensible 400 | D8: 6.23 | O8: =SUM(E8:J8) -> 0 | P8: =D8*O8 -> 0
A9: SLIDING BACK PANEL 500X700 | B9: Fond extensible 500 | D9: 7.658 | O9: =SUM(E9:J9) -> 0 | P9: =D9*O9 -> 0
A10: SHELF MONOBLOCK (WITHOUT C LABELS) 200X500 | B10: Tablette 200 x 500 | C10: SEPERATOR WITHOUT HOLES - FLAT separateur sans trou | D10: 2.4472 | O10: =SUM(E10:J10) -> 0 | P10: =D10*O10 -> 0
A11: SHELF MONOBLOCK (WITHOUT C LABELS) 200X700 | B11: Tablette 200 x 700 | C11: SEPERATOR WITHOUT HOLES - FLAT separateur sans trou | D11: 3.38744 | O11: =SUM(E11:J11) -> 0 | P11: =D11*O11 -> 0
A12: SHELF MONOBLOCK (WITHOUT C LABELS) 200X700 | B12: Tablette 200 x 700 pour bacs soldeurs | C12: GLASS SEPERATOR PERFORATED perforation pour separateur verre | D12: 3.38744 | G12: =1*G3 -> 0 | O12: =SUM(E12:J12) -> 0 | P12: =D12*O12 -> 0
A13: SHELF MONOBLOCK (WITHOUT C LABELS) 300X700 | B13: Tabette 300 x 700 pour bacs soldeurs | C13: GLASS SEPERATOR PERFORATED perforation pour separateur verre | D13: 4.0572 | F13: =1*F3 -> 0 | O13: =SUM(E13:J13) -> 0 | P13: =D13*O13 -> 0
A14: SHELF MONOBLOCK (WITHOUT C LABELS) 400 X 700 | B14: Tabette 400 x 700 pour bacs soldeurs | C14: GLASS SEPERATOR PERFORATED perforation pour separateur verre | D14: 4.0572 | E14: =1*E3 -> 0 | O14: =SUM(E14:J14) -> 0 | P14: =D14*O14 -> 0
A15: SHELF MONOBLOCK (WITHOUT C LABELS) 200 X 500 | B15: Tabette 200 x 500 pour bacs soldeurs | C15: GLASS SEPERATOR PERFORATED perforation pour separateur verre | D15: 4.0572 | J15: =1*J3 -> 0 | O15: =SUM(E15:J15) -> 0 | P15: =D15*O15 -> 0
A16: SHELF MONOBLOCK (WITHOUT C LABELS) 300 X 500 | B16: Tabette 300 x 500 pour bacs soldeurs | C16: GLASS SEPERATOR PERFORATED perforation pour separateur verre | D16: 4.0572 | I16: =1*I3 -> 0 | O16: =SUM(E16:J16) -> 0 | P16: =D16*O16 -> 0
A17: SHELF MONOBLOCK (WITHOUT C LABELS) 400 X 500 | B17: Tabette 400 x 500 pour bacs soldeurs | C17: GLASS SEPERATOR PERFORATED perforation pour separateur verre | D17: 4.0572 | H17: =1*H3 -> 0 | O17: =SUM(E17:J17) -> 0 | P17: =D17*O17 -> 0
A18: SHELF MONOBLOCK (WITHOUT C LABELS) 300X500 | B18: Tabette 300 x 500 sans trou | C18: SEPERATOR WITHOUT HOLES - FLAT separateur sans trou | D18: 4.0572 | O18: =SUM(E18:J18) -> 0 | P18: =D18*O18 -> 0
A19: SHELF MONOBLOCK (WITHOUT C LABELS) 400X500 | B19: Tabette 400 x 500 sans trou | C19: SEPERATOR WITHOUT HOLES - FLAT separateur sans trou | D19: 4.0572 | O19: =SUM(E19:J19) -> 0 | P19: =D19*O19 -> 0
A20: SHELF MONOBLOCK (WITHOUT C LABELS) 300X700 | B20: Tabette 300 x 700 sans trou | C20: SEPERATOR WITHOUT HOLES - FLAT separateur sans trou | D20: 4.0572 | O20: =SUM(E20:J20) -> 0 | P20: =D20*O20 -> 0
A21: PERFORATED SHELF MONOBLOCK (WITHOUT C LABELS) 400X700 | B21: Tablette 400 x 700 sans trou | C21: SEPERATOR WITHOUT HOLES - FLAT separateur sans trou | D21: 5.3 | O21: =SUM(E21:J21) -> 0 | P21: =D21*O21 -> 0
